Workbook

Sheet result
A1: Trial | B1: PersonaType | C1: Age | D1: Gender | E1: DialogueFile | F1: PersonaSwitch | G1: HasName | H1: Q1 | I1: Q2 | J1: Q3 | K1: Q4 | L1: Q5 | M1: Q6 | N1: Q7 | O1: Q8 | P1: Q10 | Q1: Q11 | R1: Q12 | S1: Q13 | T1: Q14 | U1: Q15 | V1: Q16 | W1: Q17 | X1: Q18 | Y1: Q19 | Z1: Q20
A2: 0 | B2: SRIHT | C2: 70-79 | D2: Female | E2: ItoI_noname.txt | F2: なし | G2: なし | H2: 2 | I2: 2 | J2: 1 | K2: 1 | L2: 3 | M2: 2 | N2: 2 | O2: 1 | P2: 2 | Q2: 3 | R2: 1 | S2: 1 | T2: 2 | U2: 1 | V2: 3 | W2: 2 | X2: 2 | Y2: 1 | Z2: 1
A3: 1 | B3: SRIHT | C3: 40-49 | D3: Male | E3: ItoE_noname.txt | F3: あり | G3: なし | H3: 3 | I3: 2 | J3: 1 | K3: 0 | L3: 3 | M3: 1 | N3: 2 | O3: 1 | P3: 1 | Q3: 2 | R3: 0 | S3: 1 | T3: 4 | U3: 0 | V3: 2 | W3: 1 | X3: 2 | Y3: 0 | Z3: 0
A4: 2 | B4: SRIHT | C4: 60-69 | D4: Female | E4: ItoI_name.txt | F4: なし | G4: あり | H4: 2 | I4: 2 | J4: 0 | K4: 0 | L4: 1 | M4: 1 | N4: 2 | O4: 0 | P4: 0 | Q4: 2 | R4: 0 | S4: 0 | T4: 2 | U4: 0 | V4: 1 | W4: 0 | X4: 1 | Y4: 0 | Z4: 1
A5: 3 | B5: SRIHT | C5: 20-29 | D5: Male | E5: ItoI_name.txt | F5: なし | G5: あり | H5: 3 | I5: 2 | J5: 1 | K5: 0 | L5: 2 | M5: 1 | N5: 4 | O5: 0 | P5: 1 | Q5: 4 | R5: 0 | S5: 0 | T5: 3 | U5: 1 | V5: 2 | W5: 1 | X5: 4 | Y5: 0 | Z5: 2
A6: 4 | B6: SRIHT | C6: 20-29 | D6: Male | E6: ItoE_noname.txt | F6: あり | G6: なし | H6: 3 | I6: 2 | J6: 1 | K6: 0 | L6: 3 | M6: 2 | N6: 3 | O6: 0 | P6: 1 | Q6: 3 | R6: 0 | S6: 1 | T6: 5 | U6: 1 | V6: 4 | W6: 2 | X6: 2 | Y6: 0 | Z6: 1
A7: 5 | B7: SRIHT | C7: 40-49 | D7: Male | E7: ItoI_name.txt | F7: なし | G7: あり | H7: 3 | I7: 1 | J7: 1 | K7: 0 | L7: 3 | M7: 2 | N7: 2 | O7: 0 | P7: 1 | Q7: 2 | R7: 0 | S7: 1 | T7: 3 | U7: 1 | V7: 2 | W7: 1 | X7: 2 | Y7: 0 | Z7: 1
A8: 6 | B8: SRIHT | C8: 30-39 | D8: Male | E8: ItoE_name.txt | F8: あり | G8: あり | H8: 2 | I8: 1 | J8: 0 | K8: 0 | L8: 0 | M8: 0 | N8: 3 | O8: 0 | P8: 0 | Q8: 1 | R8: 0 | S8: 0 | T8: 1 | U8: 0 | V8: 1 | W8: 0 | X8: 1 | Y8: 0 | Z8: 1
A9: 7 | B9: SRIHT | C9: 40-49 | D9: Male | E9: ItoI_noname.txt | F9: なし | G9: なし | H9: 3 | I9: 2 | J9: 0 | K9: 0 | L9: 1 | M9: 1 | N9: 3 | O9: 0 | P9: 0 | Q9: 4 | R9: 0 | S9: 0 | T9: 2 | U9: 0 | V9: 2 | W9: 0 | X9: 2 | Y9: 0 | Z9: 1
A10: 8 | B10: SRIHT | C10: 20-29 | D10: Male | E10: ItoI_name.txt | F10: なし | G10: あり | H10: 3 | I10: 2 | J10: 1 | K10: 0 | L10: 2 | M10: 2 | N10: 3 | O10: 0 | P10: 1 | Q10: 4 | R10: 0 | S10: 0 | T10: 2 | U10: 1 | V10: 3 | W10: 1 | X10: 2 | Y10: 0 | Z10: 1
A11: 9 | B11: SRIHT | C11: 30-39 | D11: Male | E11: ItoE_noname.txt | F11: あり | G11: なし | H11: 3 | I11: 2 | J11: 0 | K11: 0 | L11: 2 | M11: 1 | N11: 2 | O11: 0 | P11: 1 | Q11: 3 | R11: 0 | S11: 0 | T11: 3 | U11: 0 | V11: 2 | W11: 1 | X11: 1 | Y11: 0 | Z11: 1
A12: 10 | B12: SRIHT | C12: 50-59 | D12: Female | E12: ItoI_noname.txt | F12: なし | G12: なし | H12: 5 | I12: 3 | J12: 1 | K12: 0 | L12: 3 | M12: 1 | N12: 2 | O12: 1 | P12: 1 | Q12: 2 | R12: 0 | S12: 1 | T12: 5 | U12: 1 | V12: 3 | W12: 1 | X12: 2 | Y12: 0 | Z12: 1
A13: 11 | B13: SRIHT | C13: 30-39 | D13: Male | E13: ItoI_name.txt | F13: なし | G13: あり | H13: 4 | I13: 3 | J13: 1 | K13: 0 | L13: 2 | M13: 3 | N13: 4 | O13: 1 | P13: 1 | Q13: 4 | R13: 0 | S13: 1 | T13: 3 | U13: 1 | V13: 4 | W13: 1 | X13: 3 | Y13: 0 | Z13: 1
... A163: 160 | B163: SRIHT | C163: 20-29 | D163: Male | E163: ItoE_noname.txt | F163: あり | G163: なし | H163: 2 | I163: 2 | J163: 1 | K163: 0 | L163: 2 | M163: 2 | N163: 3 | O163: 1 | P163: 2 | Q163: 4 | R163: 0 | S163: 0 | T163: 4 | U163: 1 | V163: 3 | W163: 1 | X163: 2 | Y163: 0 | Z163: 1

Sheet Sheet1
A1: 質問 | B1: PersonaSwitch=あり,HasName=あり | C1: PersonaSwitch=あり,HasName=なし | D1: PersonaSwitch=なし,HasName=なし | E1: PersonaSwitch=なし,HasName=あり
A2: =result!H1 -> Q1 | B2: =AVERAGEIFS(result!H$2:'result'!H$163,result!$F$2:'result'!$F$163,"あり",result!$G$2:'result'!$G$163,"あり") -> 3.2857143 | C2: =AVERAGEIFS(result!H$2:'result'!H$163,result!$F$2:'result'!$F$163,"あり",result!$G$2:'result'!$G$163,"なし") -> 3.4 | D2: =AVERAGEIFS(result!H$2:'result'!H$163,result!$F$2:'result'!$F$163,"なし",result!$G$2:'result'!$G$163,"なし") -> 2.9714286 | E2: =AVERAGEIFS(result!H$2:'result'!H$163,result!$F$2:'result'!$F$163,"なし",result!$G$2:'result'!$G$163,"あり") -> 3.2982456
A3: =result!I1 -> Q2 | B3: =AVERAGEIFS(result!I$2:'result'!I$163,result!$F$2:'result'!$F$163,"あり",result!$G$2:'result'!$G$163,"あり") -> 2.2571429 | C3: =AVERAGEIFS(result!I$2:'result'!I$163,result!$F$2:'result'!$F$163,"あり",result!$G$2:'result'!$G$163,"なし") -> 2.4 | D3: =AVERAGEIFS(result!I$2:'result'!I$163,result!$F$2:'result'!$F$163,"なし",result!$G$2:'result'!$G$163,"なし") -> 1.9714286 | E3: =AVERAGEIFS(result!I$2:'result'!I$163,result!$F$2:'result'!$F$163,"なし",result!$G$2:'result'!$G$163,"あり") -> 2.1754386
A4: =result!J1 -> Q3 | B4: =AVERAGEIFS(result!J$2:'result'!J$163,result!$F$2:'result'!$F$163,"あり",result!$G$2:'result'!$G$163,"あり") -> 1.0857143 | C4: =AVERAGEIFS(result!J$2:'result'!J$163,result!$F$2:'result'!$F$163,"あり",result!$G$2:'result'!$G$163,"なし") -> 1.0285714 | D4: =AVERAGEIFS(result!J$2:'result'!J$163,result!$F$2:'result'!$F$163,"なし",result!$G$2:'result'!$G$163,"なし") -> 0.91428571 | E4: =AVERAGEIFS(result!J$2:'result'!J$163,result!$F$2:'result'!$F$163,"なし",result!$G$2:'result'!$G$163,"あり") -> 0.92982456
A5: =result!K1 -> Q4 | B5: =AVERAGEIFS(result!K$2:'result'!K$163,result!$F$2:'result'!$F$163,"あり",result!$G$2:'result'!$G$163,"あり") -> 0.14285714 | C5: =AVERAGEIFS(result!K$2:'result'!K$163,result!$F$2:'result'!$F$163,"あり",result!$G$2:'result'!$G$163,"なし") -> 0.25714286 | D5: =AVERAGEIFS(result!K$2:'result'!K$163,result!$F$2:'result'!$F$163,"なし",result!$G$2:'result'!$G$163,"なし") -> 0.057142857 | E5: =AVERAGEIFS(result!K$2:'result'!K$163,result!$F$2:'result'!$F$163,"なし",result!$G$2:'result'!$G$163,"あり") -> 0.087719298
A6: =result!L1 -> Q5 | B6: =AVERAGEIFS(result!L$2:'result'!L$163,result!$F$2:'result'!$F$163,"あり",result!$G$2:'result'!$G$163,"あり") -> 2.6571429 | C6: =AVERAGEIFS(result!L$2:'result'!L$163,result!$F$2:'result'!$F$163,"あり",result!$G$2:'result'!$G$163,"なし") -> 2.5428571 | D6: =AVERAGEIFS(result!L$2:'result'!L$163,result!$F$2:'result'!$F$163,"なし",result!$G$2:'result'!$G$163,"なし") -> 2.3714286 | E6: =AVERAGEIFS(result!L$2:'result'!L$163,result!$F$2:'result'!$F$163,"なし",result!$G$2:'result'!$G$163,"あり") -> 2.3684211
A7: =result!M1 -> Q6 | B7: =AVERAGEIFS(result!M$2:'result'!M$163,result!$F$2:'result'!$F$163,"あり",result!$G$2:'result'!$G$163,"あり") -> 1.5142857 | C7: =AVERAGEIFS(result!M$2:'result'!M$163,result!$F$2:'result'!$F$163,"あり",result!$G$2:'result'!$G$163,"なし") -> 1.6285714 | D7: =AVERAGEIFS(result!M$2:'result'!M$163,result!$F$2:'result'!$F$163,"なし",result!$G$2:'result'!$G$163,"なし") -> 1.4 | E7: =AVERAGEIFS(result!M$2:'result'!M$163,result!$F$2:'result'!$F$163,"なし",result!$G$2:'result'!$G$163,"あり") -> 1.5789474
A8: =result!N1 -> Q7 | B8: =AVERAGEIFS(result!N$2:'result'!N$163,result!$F$2:'result'!$F$163,"あり",result!$G$2:'result'!$G$163,"あり") -> 4.8 | C8: =AVERAGEIFS(result!N$2:'result'!N$163,result!$F$2:'result'!$F$163,"あり",result!$G$2:'result'!$G$163,"なし") -> 2.9142857 | D8: =AVERAGEIFS(result!N$2:'result'!N$163,result!$F$2:'result'!$F$163,"なし",result!$G$2:'result'!$G$163,"なし") -> 2.4285714 | E8: =AVERAGEIFS(result!N$2:'result'!N$163,result!$F$2:'result'!$F$163,"なし",result!$G$2:'result'!$G$163,"あり") -> 2.9824561
A9: =result!O1 -> Q8 | B9: =AVERAGEIFS(result!O$2:'result'!O$163,result!$F$2:'result'!$F$163,"あり",result!$G$2:'result'!$G$163,"あり") -> 0.74285714 | C9: =AVERAGEIFS(result!O$2:'result'!O$163,result!$F$2:'result'!$F$163,"あり",result!$G$2:'result'!$G$163,"なし") -> 0.71428571 | D9: =AVERAGEIFS(result!O$2:'result'!O$163,result!$F$2:'result'!$F$163,"なし",result!$G$2:'result'!$G$163,"なし") -> 0.57142857 | E9: =AVERAGEIFS(result!O$2:'result'!O$163,result!$F$2:'result'!$F$163,"なし",result!$G$2:'result'!$G$163,"あり") -> 0.49122807
A10: =result!P1 -> Q10 | B10: =AVERAGEIFS(result!P$2:'result'!P$163,result!$F$2:'result'!$F$163,"あり",result!$G$2:'result'!$G$163,"あり") -> 1.4285714 | C10: =AVERAGEIFS(result!P$2:'result'!P$163,result!$F$2:'result'!$F$163,"あり",result!$G$2:'result'!$G$163,"なし") -> 1.2285714 | D10: =AVERAGEIFS(result!P$2:'result'!P$163,result!$F$2:'result'!$F$163,"なし",result!$G$2:'result'!$G$163,"なし") -> 1.0857143 | E10: =AVERAGEIFS(result!P$2:'result'!P$163,result!$F$2:'result'!$F$163,"なし",result!$G$2:'result'!$G$163,"あり") -> 1.0701754
A11: =result!Q1 -> Q11 | B11: =AVERAGEIFS(result!Q$2:'result'!Q$163,result!$F$2:'result'!$F$163,"あり",result!$G$2:'result'!$G$163,"あり") -> 3.3714286 | C11: =AVERAGEIFS(result!Q$2:'result'!Q$163,result!$F$2:'result'!$F$163,"あり",result!$G$2:'result'!$G$163,"なし") -> 3.4285714 | D11: =AVERAGEIFS(result!Q$2:'result'!Q$163,result!$F$2:'result'!$F$163,"なし",result!$G$2:'result'!$G$163,"なし") -> 3.3428571 | E11: =AVERAGEIFS(result!Q$2:'result'!Q$163,result!$F$2:'result'!$F$163,"なし",result!$G$2:'result'!$G$163,"あり") -> 3.3684211
A12: =result!R1 -> Q12 | B12: =AVERAGEIFS(result!R$2:'result'!R$163,result!$F$2:'result'!$F$163,"あり",result!$G$2:'result'!$G$163,"あり") -> 0.17142857 | C12: =AVERAGEIFS(result!R$2:'result'!R$163,result!$F$2:'result'!$F$163,"あり",result!$G$2:'result'!$G$163,"なし") -> 0.25714286 | D12: =AVERAGEIFS(result!R$2:'result'!R$163,result!$F$2:'result'!$F$163,"なし",result!$G$2:'result'!$G$163,"なし") -> 0.085714286 | E12: =AVERAGEIFS(result!R$2:'result'!R$163,result!$F$2:'result'!$F$163,"なし",result!$G$2:'result'!$G$163,"あり") -> 0.087719298
A13: =result!S1 -> Q13 | B13: =AVERAGEIFS(result!S$2:'result'!S$163,result!$F$2:'result'!$F$163,"あり",result!$G$2:'result'!$G$163,"あり") -> 0.94285714 | C13: =AVERAGEIFS(result!S$2:'result'!S$163,result!$F$2:'result'!$F$163,"あり",result!$G$2:'result'!$G$163,"なし") -> 0.82857143 | D13: =AVERAGEIFS(result!S$2:'result'!S$163,result!$F$2:'result'!$F$163,"なし",result!$G$2:'result'!$G$163,"なし") -> 0.82857143 | E13: =AVERAGEIFS(result!S$2:'result'!S$163,result!$F$2:'result'!$F$163,"なし",result!$G$2:'result'!$G$163,"あり") -> 0.71929825
A14: =result!T1 -> Q14 | B14: =AVERAGEIFS(result!T$2:'result'!T$163,result!$F$2:'result'!$F$163,"あり",result!$G$2:'result'!$G$163,"あり") -> 3.2 | C14: =AVERAGEIFS(result!T$2:'result'!T$163,result!$F$2:'result'!$F$163,"あり",result!$G$2:'result'!$G$163,"なし") -> 3.4 | D14: =AVERAGEIFS(result!T$2:'result'!T$163,result!$F$2:'result'!$F$163,"なし",result!$G$2:'result'!$G$163,"なし") -> 3.2857143 | E14: =AVERAGEIFS(result!T$2:'result'!T$163,result!$F$2:'result'!$F$163,"なし",result!$G$2:'result'!$G$163,"あり") -> 3.4561404
A15: =result!U1 -> Q15 | B15: =AVERAGEIFS(result!U$2:'result'!U$163,result!$F$2:'result'!$F$163,"あり",result!$G$2:'result'!$G$163,"あり") -> 0.97142857 | C15: =AVERAGEIFS(result!U$2:'result'!U$163,result!$F$2:'result'!$F$163,"あり",result!$G$2:'result'!$G$163,"なし") -> 0.77142857 | D15: =AVERAGEIFS(result!U$2:'result'!U$163,result!$F$2:'result'!$F$163,"なし",result!$G$2:'result'!$G$163,"なし") -> 0.62857143 | E15: =AVERAGEIFS(result!U$2:'result'!U$163,result!$F$2:'result'!$F$163,"なし",result!$G$2:'result'!$G$163,"あり") -> 0.8245614
A16: =result!V1 -> Q16 | B16: =AVERAGEIFS(result!V$2:'result'!V$163,result!$F$2:'result'!$F$163,"あり",result!$G$2:'result'!$G$163,"あり") -> 3.0285714 | C16: =AVERAGEIFS(result!V$2:'result'!V$163,result!$F$2:'result'!$F$163,"あり",result!$G$2:'result'!$G$163,"なし") -> 2.6285714 | D16: =AVERAGEIFS(result!V$2:'result'!V$163,result!$F$2:'result'!$F$163,"なし",result!$G$2:'result'!$G$163,"なし") -> 2.4 | E16: =AVERAGEIFS(result!V$2:'result'!V$163,result!$F$2:'result'!$F$163,"なし",result!$G$2:'result'!$G$163,"あり") -> 2.5964912
A17: =result!W1 -> Q17 | B17: =AVERAGEIFS(result!W$2:'result'!W$163,result!$F$2:'result'!$F$163,"あり",result!$G$2:'result'!$G$163,"あり") -> 1.1714286 | C17: =AVERAGEIFS(result!W$2:'result'!W$163,result!$F$2:'result'!$F$163,"あり",result!$G$2:'result'!$G$163,"なし") -> 1.1714286 | D17: =AVERAGEIFS(result!W$2:'result'!W$163,result!$F$2:'result'!$F$163,"なし",result!$G$2:'result'!$G$163,"なし") -> 0.97142857 | E17: =AVERAGEIFS(result!W$2:'result'!W$163,result!$F$2:'result'!$F$163,"なし",result!$G$2:'result'!$G$163,"あり") -> 1.0175439
A18: =result!X1 -> Q18 | B18: =AVERAGEIFS(result!X$2:'result'!X$163,result!$F$2:'result'!$F$163,"あり",result!$G$2:'result'!$G$163,"あり") -> 2.3142857 | C18: =AVERAGEIFS(result!X$2:'result'!X$163,result!$F$2:'result'!$F$163,"あり",result!$G$2:'result'!$G$163,"なし") -> 2.0857143 | D18: =AVERAGEIFS(result!X$2:'result'!X$163,result!$F$2:'result'!$F$163,"なし",result!$G$2:'result'!$G$163,"なし") -> 1.8571429 | E18: =AVERAGEIFS(result!X$2:'result'!X$163,result!$F$2:'result'!$F$163,"なし",result!$G$2:'result'!$G$163,"あり") -> 2.3333333
A19: =result!Y1 -> Q19 | B19: =AVERAGEIFS(result!Y$2:'result'!Y$163,result!$F$2:'result'!$F$163,"あり",result!$G$2:'result'!$G$163,"あり") -> 0.22857143 | C19: =AVERAGEIFS(result!Y$2:'result'!Y$163,result!$F$2:'result'!$F$163,"あり",result!$G$2:'result'!$G$163,"なし") -> 0.25714286 | D19: =AVERAGEIFS(result!Y$2:'result'!Y$163,result!$F$2:'result'!$F$163,"なし",result!$G$2:'result'!$G$163,"なし") -> 0.085714286 | E19: =AVERAGEIFS(result!Y$2:'result'!Y$163,result!$F$2:'result'!$F$163,"なし",result!$G$2:'result'!$G$163,"あり") -> 0.12280702
A20: =result!Z1 -> Q20 | B20: =AVERAGEIFS(result!Z$2:'result'!Z$163,result!$F$2:'result'!$F$163,"あり",result!$G$2:'result'!$G$163,"あり") -> 1.7428571 | C20: =AVERAGEIFS(result!Z$2:'result'!Z$163,result!$F$2:'result'!$F$163,"あり",result!$G$2:'result'!$G$163,"なし") -> 1.4 | D20: =AVERAGEIFS(result!Z$2:'result'!Z$163,result!$F$2:'result'!$F$163,"なし",result!$G$2:'result'!$G$163,"なし") -> 1.2857143 | E20: =AVERAGEIFS(result!Z$2:'result'!Z$163,result!$F$2:'result'!$F$163,"なし",result!$G$2:'result'!$G$163,"あり") -> 1.6140351

Sheet result_h
A1: フィルタ 3 | B1: フィルタ 4 | C1: ID | D1: 言語設定 | E1: 入力開始日時 | F1: 入力終了日時 | G1: システムファイル | H1: 同意の有無 | I1: 理解しました | J1: 内容の確認1 | K1: 内容の確認2 | L1: 内容の確認3 | M1: 内容の確認4 | N1: 1. AIは人間らしい振る舞いをする | O1: 2. AIは生き物のように反応する | P1: 3. AIは利用しやすい | Q1: 4. AIはタスクをうまく行う | R1: 5. AIは好感が持てる | S1: 6. AIは社会に馴染むことができる | T1: 7. AIには独自の個性がある | U1: 8. 将来またこのAIを利用したいと思う | V1: 10. AIの言動は見ていて楽しい | W1: 11. AIとのやりとりは注意を引く | X1: 12. AIは信頼できる | Y1: 13. AIと協力してタスクを行うことができた | Z1: 14. AIは気を配っている | AA1: 15. AIの言動は合理的である | AB1: 16. AIの言動には意図がある | AC1: 17. AIとのやりとりを好意的に受け止めている | AD1: 18. AIは社会的な存在感がある | AE1: 19. 他の人はAIを使うことをこの勧めると思う | AF1: 20. AIには感情がある | AG1: AIの性格は変わっていない | AH1: AIの性格は初めのチャットの途中で変わった | AI1: AIの性格はチャットを新規作成した際に変わった | AJ1: AIの性格はチャットを新規作成後の<br>チャットの途中に変わった | AK1: ピクト | AL1: オルタ | AM1: モーリッツ | AN1: 左記以外 | AO1: 他に依頼したいことができたため | AP1: 予定していた依頼がすべて無事に完了したため | AQ1: AIからチャットを新規作成するように指示されたため | AR1: 何度依頼しても期待した画像が出力されなかったため | AS1: 性別 | AT1: 年齢 | AU1: 感想 | AV1: 人格切り替え | AW1: 名前 | AX1: 回答者 | AY1: 質問2 | AZ1: 質問3 | BA1: 一つずらす | BB1: 適切
A2: 1 | B2: 0 | C2: nszw26001_WOjXwNvGX9 | D2: ja | E2: 2026-01-27_20-02-33 | F2: 2026-01-27_20-05-52 | G2: iframegid:conf/iframe/chatItoI_name_js/index.html | H2: 同意する | I2: 理解しました | J2: AIとのチャットの様子を視聴する． | K2: あなた自身がユーザになったつもりでチャットの様子を視聴する | L2: チャット画面をスクロール，またはチャット画面右側に表示されるスクロールバーをドラッグすることでAIとのチャットを見返すことができる． | M2: AIへの印象の評価は，あまり深く考え込まずに自分が感じた印象で評価する． | N2: 4 | O2: 5 | P2: 5 | Q2: 5 | R2: 5 | S2: 5 | T2: 5 | U2: 6 | V2: 5 | W2: 6 | X2: 6 | Y2: 7 | Z2: 6 | AA2: 6 | AB2: 7 | AC2: 7 | AD2: 7 | AE2: 7 | AF2: 7 | AG2: 1 | AH2: 0 | AI2: 0 | AJ2: 0 | AK2: 0 | AL2: 0 | AM2: 1 | AN2: 0 | AO2: 0 | AP2: 0 | AQ2: 0 | AR2: 1 | AS2: 男 | AT2: 44 | AV2: なし | AW2: あり | AX2: 人間 | AY2: 1 | BA2: TRUE | BB2: TRUE
A3: 0 | B3: 1 | C3: nszw26001_Ycja2TN5dX | D3: ja | E3: 2026-01-27_20-02-40 | F3: 2026-01-27_20-05-58 | G3: iframegid:conf/iframe/chatItoE_noname_js/index.html | H3: 同意する | I3: 理解しました | J3: AIとのチャットの様子を視聴する． | K3: あなた自身がユーザになったつもりでチャットの様子を視聴する | L3: チャット画面をスクロール，またはチャット画面右側に表示されるスクロールバーをドラッグすることでAIとのチャットを見返すことができる． | M3: AIへの印象の評価は，あまり深く考え込まずに自分が感じた印象で評価する． | N3: 9 | O3: 8 | P3: 9 | Q3: 8 | R3: 8 | S3: 8 | T3: 9 | U3: 9 | V3: 9 | W3: 8 | X3: 8 | Y3: 8 | Z3: 9 | AA3: 9 | AB3: 7 | AC3: 9 | AD3: 8 | AE3: 9 | AF3: 6 | AG3: 1 | AH3: 0 | AI3: 0 | AJ3: 0 | AK3: 0 | AL3: 0 | AM3: 0 | AN3: 1 | AO3: 0 | AP3: 0 | AQ3: 0 | AR3: 1 | AS3: 男 | AT3: 40 | AV3: あり | AW3: なし | AX3: 人間 | AY3: 1 | BA3: TRUE | BB3: TRUE
A4: 1 | B4: 0 | C4: nszw26001_mqQRm4ZW3E | D4: ja | E4: 2026-01-27_20-02-32 | F4: 2026-01-27_20-06-41 | G4: iframegid:conf/iframe/chatItoI_name_js/index.html | H4: 同意する | I4: 理解しました | J4: AIとのチャットの様子を視聴する． | K4: あなた自身がユーザになったつもりでチャットの様子を視聴する | L4: チャット画面をスクロール，またはチャット画面右側に表示されるスクロールバーをドラッグすることでAIとのチャットを見返すことができる． | M4: AIへの印象の評価は，あまり深く考え込まずに自分が感じた印象で評価する． | N4: 2 | O4: 2 | P4: 6 | Q4: 4 | R4: 5 | S4: 5 | T4: 5 | U4: 2 | V4: 5 | W4: 6 | X4: 6 | Y4: 7 | Z4: 4 | AA4: 7 | AB4: 1 | AC4: 6 | AD4: 6 | AE4: 1 | AF4: 0 | AG4: 1 | AH4: 0 | AI4: 0 | AJ4: 0 | AK4: 0 | AL4: 0 | AM4: 1 | AN4: 0 | AO4: 0 | AP4: 0 | AQ4: 0 | AR4: 1 | AS4: 男 | AT4: 48 | AV4: なし | AW4: あり | AX4: 人間 | AY4: 1 | BA4: TRUE | BB4: TRUE
A5: 0 | B5: 0 | C5: nszw26001_yfkynHPo71 | D5: ja | E5: 2026-01-27_20-02-36 | F5: 2026-01-27_20-06-43 | G5: iframegid:conf/iframe/chatItoI_noname_js/index.html | H5: 同意する | I5: 理解しました | J5: AIとのチャットの様子を視聴する． | K5: あなた自身がユーザになったつもりでチャットの様子を視聴する | L5: チャット画面をスクロール，またはチャット画面右側に表示されるスクロールバーをドラッグすることでAIとのチャットを見返すことができる． | M5: AIへの印象の評価は，あまり深く考え込まずに自分が感じた印象で評価する． | N5: 2 | O5: 3 | P5: 2 | Q5: 3 | R5: 7 | S5: 5 | T5: 9 | U5: 2 | V5: 3 | W5: 4 | X5: 2 | Y5: 5 | Z5: 7 | AA5: 4 | AB5: 3 | AC5: 5 | AD5: 4 | AE5: 1 | AF5: 3 | AG5: 0 | AH5: 0 | AI5: 1 | AJ5: 0 | AK5: 0 | AL5: 0 | AM5: 0 | AN5: 1 | AO5: 0 | AP5: 0 | AQ5: 0 | AR5: 1 | AS5: 男 | AT5: 55 | AV5: なし | AW5: なし | AX5: 人間 | AY5: 1 | BA5: TRUE | BB5: TRUE
A6: 1 | B6: 1 | C6: nszw26001_D2VV5UUtiX | D6: ja | E6: 2026-01-27_20-02-46 | F6: 2026-01-27_20-06-49 | G6: iframegid:conf/iframe/chatItoE_name_js/index.html | H6: 同意する | I6: 理解しました | J6: AIとのチャットの様子を視聴する． | K6: あなた自身がユーザになったつもりでチャットの様子を視聴する | L6: チャット画面をスクロール，またはチャット画面右側に表示されるスクロールバーをドラッグすることでAIとのチャットを見返すことができる． | M6: AIへの印象の評価は，あまり深く考え込まずに自分が感じた印象で評価する． | N6: 3 | O6: 3 | P6: 0 | Q6: 0 | R6: 0 | S6: 0 | T6: 8 | U6: 0 | V6: 2 | W6: 5 | X6: 0 | Y6: 0 | Z6: 0 | AA6: 0 | AB6: 5 | AC6: 0 | AD6: 5 | AE6: 0 | AF6: 5 | AG6: 1 | AH6: 0 | AI6: 0 | AJ6: 0 | AK6: 1 | AL6: 0 | AM6: 1 | AN6: 0 | AO6: 0 | AP6: 0 | AQ6: 0 | AR6: 1 | AS6: 男 | AT6: 51 | AV6: あり | AW6: あり | AX6: 人間 | AY6: 1 | BA6: TRUE | BB6: TRUE
A7: 0 | B7: 1 | C7: nszw26001_oS2fgO3tPE | D7: ja | E7: 2026-01-27_20-02-44 | F7: 2026-01-27_20-07-10 | G7: iframegid:conf/iframe/chatItoE_noname_js/index.html | H7: 同意する | I7: 理解しました | J7: AIとのチャットの様子を視聴する． | K7: あなた自身がユーザになったつもりでチャットの様子を視聴する | L7: チャット画面をスクロール，またはチャット画面右側に表示されるスクロールバーをドラッグすることでAIとのチャットを見返すことができる． | M7: AIへの印象の評価は，あまり深く考え込まずに自分が感じた印象で評価する． | N7: 1 | O7: 2 | P7: 1 | Q7: 4 | R7: 2 | S7: 2 | T7: 1 | U7: 0 | V7: 1 | W7: 1 | X7: 7 | Y7: 2 | Z7: 2 | AA7: 3 | AB7: 2 | AC7: 3 | AD7: 1 | AE7: 2 | AF7: 0 | AG7: 0 | AH7: 0 | AI7: 1 | AJ7: 0 | AK7: 0 | AL7: 0 | AM7: 0 | AN7: 1 | AO7: 0 | AP7: 0 | AQ7: 0 | AR7: 1 | AS7: 男 | AT7: 47 | AU7: ここまで無能？なAIはひどい | AV7: あり | AW7: なし | AX7: 人間 | AY7: 1 | BA7: TRUE | BB7: TRUE
A8: 1 | B8: 0 | C8: nszw26001_ZraTpYwOfb | D8: ja | E8: 2026-01-27_20-02-31 | F8: 2026-01-27_20-07-03 | G8: iframegid:conf/iframe/chatItoI_name_js/index.html | H8: 同意する | I8: 理解しました | J8: AIとのチャットの様子を視聴する． | K8: あなた自身がユーザになったつもりでチャットの様子を視聴する | L8: チャット画面をスクロール，またはチャット画面右側に表示されるスクロールバーをドラッグすることでAIとのチャットを見返すことができる． | M8: AIへの印象の評価は，あまり深く考え込まずに自分が感じた印象で評価する． | N8: 3 | O8: 1 | P8: 0 | Q8: 0 | R8: 0 | S8: 1 | T8: 0 | U8: 2 | V8: 0 | W8: 1 | X8: 0 | Y8: 1 | Z8: 0 | AA8: 0 | AB8: 0 | AC8: 0 | AD8: 1 | AE8: 0 | AF8: 0 | AG8: 1 | AH8: 0 | AI8: 0 | AJ8: 0 | AK8: 0 | AL8: 0 | AM8: 1 | AN8: 0 | AO8: 0 | AP8: 0 | AQ8: 0 | AR8: 1 | AS8: 男 | AT8: 49 | AU8: ない | AV8: なし | AW8: あり | AX8: 人間 | AY8: 1 | BA8: TRUE | BB8: TRUE
A9: 1 | B9: 0 | C9: nszw26001_TogE9asSS2 | D9: ja | E9: 2026-01-27_20-02-33 | F9: 2026-01-27_20-07-07 | G9: iframegid:conf/iframe/chatItoI_name_js/index.html | H9: 同意する | I9: 理解しました | J9: AIとのチャットの様子を視聴する． | K9: あなた自身がユーザになったつもりでチャットの様子を視聴する | L9: チャット画面をスクロール，またはチャット画面右側に表示されるスクロールバーをドラッグすることでAIとのチャットを見返すことができる． | M9: AIへの印象の評価は，あまり深く考え込まずに自分が感じた印象で評価する． | N9: 2 | O9: 1 | P9: 0 | Q9: 0 | R9: 1 | S9: 2 | T9: 4 | U9: 0 | V9: 1 | W9: 2 | X9: 0 | Y9: 0 | Z9: 1 | AA9: 0 | AB9: 0 | AC9: 1 | AD9: 1 | AE9: 0 | AF9: 1 | AG9: 1 | AH9: 0 | AI9: 0 | AJ9: 0 | AK9: 0 | AL9: 0 | AM9: 1 | AN9: 0 | AO9: 0 | AP9: 0 | AQ9: 0 | AR9: 1 | AS9: 男 | AT9: 43 | AU9: 同様のシチュエーションに遭遇したことがあったことを思い出しました。 | AV9: なし | AW9: あり | AX9: 人間 | AY9: 1 | BA9: TRUE | BB9: TRUE
A10: 0 | B10: 1 | C10: nszw26001_Q0XtdMSRnG | D10: ja | E10: 2026-01-27_20-03-21 | F10: 2026-01-27_20-07-16 | G10: iframegid:conf/iframe/chatItoE_noname_js/index.html | H10: 同意する | I10: 理解しました | J10: AIとのチャットの様子を視聴する． | K10: あなた自身がユーザになったつもりでチャットの様子を視聴する | L10: チャット画面をスクロール，またはチャット画面右側に表示されるスクロールバーをドラッグすることでAIとのチャットを見返すことができる． | M10: AIへの印象の評価は，あまり深く考え込まずに自分が感じた印象で評価する． | N10: 0 | O10: 0 | P10: 5 | Q10: 0 | R10: 5 | S10: 5 | T10: 5 | U10: 0 | V10: 0 | W10: 0 | X10: 0 | Y10: 0 | Z10: 5 | AA10: 5 | AB10: 5 | AC10: 5 | AD10: 5 | AE10: 0 | AF10: 0 | AG10: 1 | AH10: 0 | AI10: 0 | AJ10: 0 | AK10: 0 | AL10: 0 | AM10: 0 | AN10: 1 | AO10: 0 | AP10: 0 | AQ10: 0 | AR10: 1 | AS10: 男 | AT10: 55 | AV10: あり | AW10: なし | AX10: 人間 | AY10: 1 | BA10: TRUE | BB10: TRUE
A11: 0 | B11: 1 | C11: nszw26001_hpDK6GAc6r | D11: ja | E11: 2026-01-27_20-02-38 | F11: 2026-01-27_20-07-17 | G11: iframegid:conf/iframe/chatItoE_noname_js/index.html | H11: 同意する | I11: 理解しました | J11: AIとのチャットの様子を視聴する． | K11: あなた自身がユーザになったつもりでチャットの様子を視聴する | L11: チャット画面をスクロール，またはチャット画面右側に表示されるスクロールバーをドラッグすることでAIとのチャットを見返すことができる． | M11: AIへの印象の評価は，あまり深く考え込まずに自分が感じた印象で評価する． | N11: 6 | O11: 6 | P11: 4 | Q11: 4 | R11: 6 | S11: 5 | T11: 6 | U11: 0 | V11: 6 | W11: 6 | X11: 7 | Y11: 5 | Z11: 6 | AA11: 7 | AB11: 4 | AC11: 7 | AD11: 6 | AE11: 1 | AF11: 5 | AG11: 1 | AH11: 0 | AI11: 0 | AJ11: 0 | AK11: 0 | AL11: 0 | AM11: 0 | AN11: 1 | AO11: 0 | AP11: 0 | AQ11: 0 | AR11: 1 | AS11: 男 | AT11: 40 | AV11: あり | AW11: なし | AX11: 人間 | AY11: 1 | BA11: TRUE | BB11: TRUE
A12: 0 | B12: 1 | C12: nszw26001_lLebZwjEIn | D12: ja | E12: 2026-01-27_20-02-32 | F12: 2026-01-27_20-07-24 | G12: iframegid:conf/iframe/chatItoE_noname_js/index.html | H12: 同意する | I12: 理解しました | J12: AIとのチャットの様子を視聴する． | K12: あなた自身がユーザになったつもりでチャットの様子を視聴する | L12: チャット画面をスクロール，またはチャット画面右側に表示されるスクロールバーをドラッグすることでAIとのチャットを見返すことができる． | M12: AIへの印象の評価は，あまり深く考え込まずに自分が感じた印象で評価する． | N12: 2 | O12: 1 | P12: 1 | Q12: 0 | R12: 1 | S12: 1 | T12: 5 | U12: 0 | V12: 5 | W12: 5 | X12: 3 | Y12: 3 | Z12: 2 | AA12: 2 | AB12: 5 | AC12: 1 | AD12: 4 | AE12: 1 | AF12: 1 | AG12: 1 | AH12: 0 | AI12: 0 | AJ12: 0 | AK12: 0 | AL12: 0 | AM12: 0 | AN12: 1 | AO12: 0 | AP12: 0 | AQ12: 0 | AR12: 1 | AS12: 男 | AT12: 49 | AU12: ない | AV12: あり | AW12: なし | AX12: 人間 | AY12: 1 | BA12: TRUE | BB12: TRUE
A13: 1 | B13: 0 | C13: nszw26001_ZdqzsdPkLf | D13: ja | E13: 2026-01-27_20-02-43 | F13: 2026-01-27_20-07-29 | G13: iframegid:conf/iframe/chatItoI_name_js/index.html | H13: 同意する | I13: 理解しました | J13: AIとのチャットの様子を視聴する． | K13: あなた自身がユーザになったつもりでチャットの様子を視聴する | L13: チャット画面をスクロール，またはチャット画面右側に表示されるスクロールバーをドラッグすることでAIとのチャットを見返すことができる． | M13: AIへの印象の評価は，あまり深く考え込まずに自分が感じた印象で評価する． | N13: 2 | O13: 3 | P13: 6 | Q13: 0 | R13: 5 | S13: 6 | T13: 6 | U13: 1 | V13: 2 | W13: 2 | X13: 1 | Y13: 5 | Z13: 3 | AA13: 4 | AB13: 4 | AC13: 3 | AD13: 4 | AE13: 1 | AF13: 7 | AG13: 1 | AH13: 0 | AI13: 0 | AJ13: 0 | AK13: 0 | AL13: 0 | AM13: 1 | AN13: 0 | AO13: 0 | AP13: 0 | AQ13: 0 | AR13: 1 | AS13: 男 | AT13: 42 | AV13: なし | AW13: あり | AX13: 人間 | AY13: 1 | BA13: TRUE | BB13: TRUE
A14: 1 | B14: 1 | C14: nszw26001_ld1WmHaCKr | D14: ja | E14: 2026-01-27_20-02-33 | F14: 2026-01-27_20-07-24 | G14: iframegid:conf/iframe/chatItoE_name_js/index.html | H14: 同意する | I14: 理解しました | J14: AIとのチャットの様子を視聴する． | K14: あなた自身がユーザになったつもりでチャットの様子を視聴する | L14: チャット画面をスクロール，またはチャット画面右側に表示されるスクロールバーをドラッグすることでAIとのチャットを見返すことができる． | M14: AIへの印象の評価は，あまり深く考え込まずに自分が感じた印象で評価する． | N14: 1 | O14: 2 | P14: 1 | Q14: 0 | R14: 0 | S14: 1 | T14: 1 | U14: 0 | V14: 0 | W14: 1 | X14: 0 | Y14: 0 | Z14: 0 | AA14: 0 | AB14: 1 | AC14: 0 | AD14: 1 | AE14: 0 | AF14: 0 | AG14: 1 | AH14: 0 | AI14: 0 | AJ14: 0 | AK14: 1 | AL14: 0 | AM14: 1 | AN14: 0 | AO14: 0 | AP14: 0 | AQ14: 0 | AR14: 1 | AS14: 男 | AT14: 46 | AV14: あり | AW14: あり | AX14: 人間 | AY14: 1 | BA14: TRUE | BB14: TRUE
A15: 1 | B15: 1 | C15: nszw26001_KRhWckzkwg | D15: ja | E15: 2026-01-27_20-02-41 | F15: 2026-01-27_20-07-27 | G15: iframegid:conf/iframe/chatItoE_name_js/index.html | H15: 同意する | I15: 理解しました | J15: AIとのチャットの様子を視聴する． | K15: あなた自身がユーザになったつもりでチャットの様子を視聴する | L15: チャット画面をスクロール，またはチャット画面右側に表示されるスクロールバーをドラッグすることでAIとのチャットを見返すことができる． | M15: AIへの印象の評価は，あまり深く考え込まずに自分が感じた印象で評価する． | N15: 5 | O15: 5 | P15: 6 | Q15: 4 | R15: 4 | S15: 5 | T15: 6 | U15: 5 | V15: 5 | W15: 5 | X15: 4 | Y15: 6 | Z15: 4 | AA15: 5 | AB15: 5 | AC15: 6 | AD15: 4 | AE15: 3 | AF15: 5 | AG15: 0 | AH15: 0 | AI15: 1 | AJ15: 0 | AK15: 1 | AL15: 0 | AM15: 1 | AN15: 0 | AO15: 0 | AP15: 0 | AQ15: 0 | AR15: 1 | AS15: 男 | AT15: 52 | AV15: あり | AW15: あり | AX15: 人間 | AY15: 1 | BA15: TRUE | BB15: TRUE
A16: 1 | B16: 0 | C16: nszw26001_Sm7ai0HddU | D16: ja | E16: 2026-01-27_20-02-33 | F16: 2026-01-27_20-07-35 | G16: iframegid:conf/iframe/chatItoI_name_js/index.html | H16: 同意する | I16: 理解しました | J16: AIとのチャットの様子を視聴する． | K16: あなた自身がユーザになったつもりでチャットの様子を視聴する | L16: チャット画面をスクロール，またはチャット画面右側に表示されるスクロールバーをドラッグすることでAIとのチャットを見返すことができる． | M16: AIへの印象の評価は，あまり深く考え込まずに自分が感じた印象で評価する． | N16: 2 | O16: 2 | P16: 2 | Q16: 2 | R16: 2 | S16: 2 | T16: 5 | U16: 2 | V16: 2 | W16: 2 | X16: 2 | Y16: 2 | Z16: 2 | AA16: 2 | AB16: 2 | AC16: 2 | AD16: 2 | AE16: 2 | AF16: 2 | AG16: 1 | AH16: 0 | AI16: 0 | AJ16: 0 | AK16: 0 | AL16: 0 | AM16: 1 | AN16: 0 | AO16: 0 | AP16: 0 | AQ16: 0 | AR16: 1 | AS16: 男 | AT16: 54 | AU16: イラっとした | AV16: なし | AW16: あり | AX16: 人間 | AY16: 1 | BA16: TRUE | BB16: TRUE
A17: 0 | B17: 0 | C17: nszw26001_ZlMzIaZfM6 | D17: ja | E17: 2026-01-27_20-02-34 | F17: 2026-01-27_20-07-42 | G17: iframegid:conf/iframe/chatItoI_noname_js/index.html | H17: 同意する | I17: 理解しました | J17: AIとのチャットの様子を視聴する． | K17: あなた自身がユーザになったつもりでチャットの様子を視聴する | L17: チャット画面をスクロール，またはチャット画面右側に表示されるスクロールバーをドラッグすることでAIとのチャットを見返すことができる． | M17: AIへの印象の評価は，あまり深く考え込まずに自分が感じた印象で評価する． | N17: 7 | O17: 8 | P17: 7 | Q17: 2 | R17: 6 | S17: 3 | T17: 5 | U17: 2 | V17: 5 | W17: 8 | X17: 2 | Y17: 3 | Z17: 7 | AA17: 5 | AB17: 2 | AC17: 5 | AD17: 5 | AE17: 2 | AF17: 2 | AG17: 1 | AH17: 0 | AI17: 0 | AJ17: 0 | AK17: 0 | AL17: 0 | AM17: 0 | AN17: 1 | AO17: 0 | AP17: 0 | AQ17: 0 | AR17: 1 | AS17: 男 | AT17: 51 | AU17: AIはまだ発展途上の為に信用が今一出来ない。 | AV17: なし | AW17: なし | AX17: 人間 | AY17: 1 | BA17: TRUE | BB17: TRUE
A18: 0 | B18: 0 | C18: nszw26001_RsJxAWWGy2 | D18: ja | E18: 2026-01-27_20-02-58 | F18: 2026-01-27_20-07-52 | G18: iframegid:conf/iframe/chatItoI_noname_js/index.html | H18: 同意する | I18: 理解しました | J18: AIとのチャットの様子を視聴する． | K18: あなた自身がユーザになったつもりでチャットの様子を視聴する | L18: チャット画面をスクロール，またはチャット画面右側に表示されるスクロールバーをドラッグすることでAIとのチャットを見返すことができる． | M18: AIへの印象の評価は，あまり深く考え込まずに自分が感じた印象で評価する． | N18: 6 | O18: 6 | P18: 5 | Q18: 4 | R18: 6 | S18: 6 | T18: 6 | U18: 4 | V18: 6 | W18: 6 | X18: 6 | Y18: 6 | Z18: 7 | AA18: 6 | AB18: 6 | AC18: 5 | AD18: 6 | AE18: 4 | AF18: 6 | AG18: 1 | AH18: 0 | AI18: 0 | AJ18: 0 | AK18: 1 | AL18: 0 | AM18: 0 | AN18: 0 | AO18: 0 | AP18: 0 | AQ18: 0 | AR18: 1 | AS18: 男 | AT18: 47 | AU18: AIにもどかしさを覚えた | AV18: なし | AW18: なし | AX18: 人間 | AY18: 1 | BA18: TRUE | BB18: TRUE
A19: 1 | B19: 1 | C19: nszw26001_RTFlxd0LMV | D19: ja | E19: 2026-01-27_20-02-34 | F19: 2026-01-27_20-08-00 | G19: iframegid:conf/iframe/chatItoE_name_js/index.html | H19: 同意する | I19: 理解しました | J19: AIとのチャットの様子を視聴する． | K19: あなた自身がユーザになったつもりでチャットの様子を視聴する | L19: チャット画面をスクロール，またはチャット画面右側に表示されるスクロールバーをドラッグすることでAIとのチャットを見返すことができる． | M19: AIへの印象の評価は，あまり深く考え込まずに自分が感じた印象で評価する． | N19: 2 | O19: 3 | P19: 4 | Q19: 3 | R19: 1 | S19: 2 | T19: 2 | U19: 0 | V19: 3 | W19: 4 | X19: 4 | Y19: 3 | Z19: 3 | AA19: 4 | AB19: 0 | AC19: 3 | AD19: 5 | AE19: 3 | AF19: 0 | AG19: 0 | AH19: 0 | AI19: 1 | AJ19: 0 | AK19: 1 | AL19: 0 | AM19: 1 | AN19: 0 | AO19: 0 | AP19: 0 | AQ19: 0 | AR19: 1 | AS19: 男 | AT19: 45 | AU19: とくにありませんが本当にAIがこんな動きをしたら腹立たしい感じがします | AV19: あり | AW19: あり | AX19: 人間 | AY19: 1 | BA19: TRUE | BB19: TRUE
A20: 0 | B20: 1 | C20: nszw26001_rcqMk7HQgW | D20: ja | E20: 2026-01-27_20-02-37 | F20: 2026-01-27_20-08-00 | G20: iframegid:conf/iframe/chatItoE_noname_js/index.html | H20: 同意する | I20: 理解しました | J20: AIとのチャットの様子を視聴する． | K20: あなた自身がユーザになったつもりでチャットの様子を視聴する | L20: チャット画面をスクロール，またはチャット画面右側に表示されるスクロールバーをドラッグすることでAIとのチャットを見返すことができる． | M20: AIへの印象の評価は，あまり深く考え込まずに自分が感じた印象で評価する． | N20: 8 | O20: 5 | P20: 2 | Q20: 2 | R20: 1 | S20: 5 | T20: 6 | U20: 1 | V20: 3 | W20: 5 | X20: 1 | Y20: 1 | Z20: 3 | AA20: 1 | AB20: 0 | AC20: 0 | AD20: 2 | AE20: 0 | AF20: 0 | AG20: 1 | AH20: 0 | AI20: 0 | AJ20: 0 | AK20: 0 | AL20: 0 | AM20: 0 | AN20: 1 | AO20: 0 | AP20: 0 | AQ20: 0 | AR20: 1 | AS20: 男 | AT20: 40 | AV20: あり | AW20: なし | AX20: 人間 | AY20: 1 | BA20: TRUE | BB20: TRUE
A21: 1 | B21: 0 | C21: nszw26001_RMaQFzNVnx | D21: ja | E21: 2026-01-27_20-02-37 | F21: 2026-01-27_20-08-08 | G21: iframegid:conf/iframe/chatItoI_name_js/index.html | H21: 同意する | I21: 理解しました | J21: AIとのチャットの様子を視聴する． | K21: あなた自身がユーザになったつもりでチャットの様子を視聴する | L21: チャット画面をスクロール，またはチャット画面右側に表示されるスクロールバーをドラッグすることでAIとのチャットを見返すことができる． | M21: AIへの印象の評価は，あまり深く考え込まずに自分が感じた印象で評価する． | N21: 8 | O21: 8 | P21: 2 | Q21: 2 | R21: 2 | S21: 2 | T21: 7 | U21: 2 | V21: 2 | W21: 3 | X21: 1 | Y21: 2 | Z21: 2 | AA21: 2 | AB21: 2 | AC21: 1 | AD21: 6 | AE21: 1 | AF21: 1 | AG21: 1 | AH21: 0 | AI21: 0 | AJ21: 0 | AK21: 0 | AL21: 0 | AM21: 1 | AN21: 0 | AO21: 0 | AP21: 0 | AQ21: 0 | AR21: 1 | AS21: 男 | AT21: 40 | AU21: チャットのやり取りで上手くいかないのを眺めているのはもどかしかった | AV21: なし | AW21: あり | AX21: 人間 | AY21: 1 | BA21: TRUE | BB21: TRUE
A22: 1 | B22: 0 | C22: nszw26001_BOohnLhhUb | D22: ja | E22: 2026-01-27_20-02-32 | F22: 2026-01-27_20-08-05 | G22: iframegid:conf/iframe/chatItoI_name_js/index.html | H22: 同意する | I22: 理解しました | J22: AIとのチャットの様子を視聴する． | K22: あなた自身がユーザになったつもりでチャットの様子を視聴する | L22: チャット画面をスクロール，またはチャット画面右側に表示されるスクロールバーをドラッグすることでAIとのチャットを見返すことができる． | M22: AIへの印象の評価は，あまり深く考え込まずに自分が感じた印象で評価する． | N22: 5 | O22: 2 | P22: 0 | Q22: 0 | R22: 0 | S22: 0 | T22: 1 | U22: 0 | V22: 5 | W22: 5 | X22: 1 | Y22: 1 | Z22: 1 | AA22: 0 | AB22: 0 | AC22: 1 | AD22: 8 | AE22: 1 | AF22: 0 | AG22: 1 | AH22: 0 | AI22: 0 | AJ22: 0 | AK22: 0 | AL22: 0 | AM22: 1 | AN22: 0 | AO22: 0 | AP22: 0 | AQ22: 0 | AR22: 1 | AS22: 男 | AT22: 39 | AU22: AI が無能だった | AV22: なし | AW22: あり | AX22: 人間 | AY22: 1 | BA22: TRUE | BB22: TRUE
A23: 1 | B23: 1 | C23: nszw26001_utEImfbfZR | D23: ja | E23: 2026-01-27_20-02-37 | F23: 2026-01-27_20-08-10 | G23: iframegid:conf/iframe/chatItoE_name_js/index.html | H23: 同意する | I23: 理解しました | J23: AIとのチャットの様子を視聴する． | K23: あなた自身がユーザになったつもりでチャットの様子を視聴する | L23: チャット画面をスクロール，またはチャット画面右側に表示されるスクロールバーをドラッグすることでAIとのチャットを見返すことができる． | M23: AIへの印象の評価は，あまり深く考え込まずに自分が感じた印象で評価する． | N23: 1 | O23: 0 | P23: 0 | Q23: 0 | R23: 0 | S23: 0 | T23: 0 | U23: 0 | V23: 0 | W23: 0 | X23: 0 | Y23: 0 | Z23: 0 | AA23: 0 | AB23: 0 | AC23: 0 | AD23: 0 | AE23: 0 | AF23: 0 | AG23: 1 | AH23: 0 | AI23: 0 | AJ23: 0 | AK23: 1 | AL23: 0 | AM23: 1 | AN23: 0 | AO23: 0 | AP23: 0 | AQ23: 0 | AR23: 1 | AS23: 男 | AT23: 42 | AV23: あり | AW23: あり | AX23: 人間 | AY23: 1 | BA23: TRUE | BB23: TRUE
A24: 1 | B24: 0 | C24: nszw26001_gFLu4vwoyu | D24: ja | E24: 2026-01-27_20-02-40 | F24: 2026-01-27_20-08-22 | G24: iframegid:conf/iframe/chatItoI_name_js/index.html | H24: 同意する | I24: 理解しました | J24: AIとのチャットの様子を視聴する． | K24: あなた自身がユーザになったつもりでチャットの様子を視聴する | L24: チャット画面をスクロール，またはチャット画面右側に表示されるスクロールバーをドラッグすることでAIとのチャットを見返すことができる． | M24: AIへの印象の評価は，あまり深く考え込まずに自分が感じた印象で評価する． | N24: 0 | O24: 0 | P24: 0 | Q24: 0 | R24: 0 | S24: 0 | T24: 1 | U24: 0 | V24: 0 | W24: 0 | X24: 0 | Y24: 0 | Z24: 0 | AA24: 0 | AB24: 0 | AC24: 0 | AD24: 1 | AE24: 0 | AF24: 0 | AG24: 1 | AH24: 0 | AI24: 0 | AJ24: 0 | AK24: 0 | AL24: 0 | AM24: 1 | AN24: 0 | AO24: 0 | AP24: 0 | AQ24: 0 | AR24: 1 | AS24: 男 | AT24: 52 | AU24: 特になし | AV24: なし | AW24: あり | AX24: 人間 | AY24: 1 | BA24: TRUE | BB24: TRUE
A25: 0 | B25: 0 | C25: nszw26001_oOuSUC4LNJ | D25: ja | E25: 2026-01-27_20-02-35 | F25: 2026-01-27_20-08-27 | G25: iframegid:conf/iframe/chatItoI_noname_js/index.html | H25: 同意する | I25: 理解しました | J25: AIとのチャットの様子を視聴する． | K25: あなた自身がユーザになったつもりでチャットの様子を視聴する | L25: チャット画面をスクロール，またはチャット画面右側に表示されるスクロールバーをドラッグすることでAIとのチャットを見返すことができる． | M25: AIへの印象の評価は，あまり深く考え込まずに自分が感じた印象で評価する． | N25: 2 | O25: 2 | P25: 1 | Q25: 0 | R25: 3 | S25: 4 | T25: 3 | U25: 0 | V25: 2 | W25: 8 | X25: 2 | Y25: 1 | Z25: 2 | AA25: 0 | AB25: 10 | AC25: 0 | AD25: 8 | AE25: 0 | AF25: 5 | AG25: 1 | AH25: 0 | AI25: 0 | AJ25: 0 | AK25: 0 | AL25: 0 | AM25: 0 | AN25: 1 | AO25: 0 | AP25: 0 | AQ25: 0 | AR25: 1 | AS25: 男 | AT25: 54 | AU25: AIの間違え方がわざとらしすぎる | AV25: なし | AW25: なし | AX25: 人間 | AY25: 1 | BA25: TRUE | BB25: TRUE
A26: 0 | B26: 0 | C26: nszw26001_b7tMT8ElYs | D26: ja | E26: 2026-01-27_20-04-05 | F26: 2026-01-27_20-08-40 | G26: iframegid:conf/iframe/chatItoI_noname_js/index.html | H26: 同意する | I26: 理解しました | J26: AIとのチャットの様子を視聴する． | K26: あなた自身がユーザになったつもりでチャットの様子を視聴する | L26: チャット画面をスクロール，またはチャット画面右側に表示されるスクロールバーをドラッグすることでAIとのチャットを見返すことができる． | M26: AIへの印象の評価は，あまり深く考え込まずに自分が感じた印象で評価する． | N26: 7 | O26: 7 | P26: 10 | Q26: 3 | R26: 5 | S26: 10 | T26: 0 | U26: 0 | V26: 10 | W26: 10 | X26: 8 | Y26: 8 | Z26: 6 | AA26: 6 | AB26: 0 | AC26: 6 | AD26: 10 | AE26: 5 | AF26: 0 | AG26: 0 | AH26: 1 | AI26: 0 | AJ26: 0 | AK26: 0 | AL26: 0 | AM26: 0 | AN26: 1 | AO26: 0 | AP26: 0 | AQ26: 0 | AR26: 1 | AS26: 男 | AT26: 58 | AV26: なし | AW26: なし | AX26: 人間 | AY26: 1 | BA26: TRUE | BB26: TRUE
A27: 0 | B27: 0 | C27: nszw26001_Xn74rUowwJ | D27: ja | E27: 2026-01-27_20-02-34 | F27: 2026-01-27_20-08-41 | G27: iframegid:conf/iframe/chatItoI_noname_js/index.html | H27: 同意する | I27: 理解しました | J27: AIとのチャットの様子を視聴する． | K27: あなた自身がユーザになったつもりでチャットの様子を視聴する | L27: チャット画面をスクロール，またはチャット画面右側に表示されるスクロールバーをドラッグすることでAIとのチャットを見返すことができる． | M27: AIへの印象の評価は，あまり深く考え込まずに自分が感じた印象で評価する． | N27: 6 | O27: 7 | P27: 3 | Q27: 1 | R27: 2 | S27: 2 | T27: 6 | U27: 0 | V27: 8 | W27: 8 | X27: 1 | Y27: 0 | Z27: 0 | AA27: 0 | AB27: 1 | AC27: 8 | AD27: 8 | AE27: 1 | AF27: 5 | AG27: 1 | AH27: 0 | AI27: 0 | AJ27: 0 | AK27: 0 | AL27: 0 | AM27: 0 | AN27: 1 | AO27: 0 | AP27: 0 | AQ27: 0 | AR27: 1 | AS27: 男 | AT27: 57 | AU27: 実験とはいえこれほど使えないAIは始めてみた | AV27: なし | AW27: なし | AX27: 人間 | AY27: 1 | BA27: TRUE | BB27: TRUE
A28: 0 | B28: 1 | C28: nszw26001_yXBhgjQcCv | D28: ja | E28: 2026-01-27_20-02-49 | F28: 2026-01-27_20-08-46 | G28: iframegid:conf/iframe/chatItoE_noname_js/index.html | H28: 同意する | I28: 理解しました | J28: AIとのチャットの様子を視聴する． | K28: あなた自身がユーザになったつもりでチャットの様子を視聴する | L28: チャット画面をスクロール，またはチャット画面右側に表示されるスクロールバーをドラッグすることでAIとのチャットを見返すことができる． | M28: AIへの印象の評価は，あまり深く考え込まずに自分が感じた印象で評価する． | N28: 0 | O28: 0 | P28: 0 | Q28: 0 | R28: 0 | S28: 0 | T28: 0 | U28: 0 | V28: 0 | W28: 6 | X28: 0 | Y28: 2 | Z28: 0 | AA28: 0 | AB28: 5 | AC28: 0 | AD28: 5 | AE28: 0 | AF28: 0 | AG28: 0 | AH28: 0 | AI28: 1 | AJ28: 0 | AK28: 0 | AL28: 0 | AM28: 0 | AN28: 1 | AO28: 0 | AP28: 0 | AQ28: 0 | AR28: 1 | AS28: 男 | AT28: 51 | AU28: AIが指示を理解していなくて驚いた。 | AV28: あり | AW28: なし | AX28: 人間 | AY28: 1 | BA28: TRUE | BB28: TRUE
A29: 1 | B29: 1 | C29: nszw26001_FrdV7fxBam | D29: ja | E29: 2026-01-27_20-04-34 | F29: 2026-01-27_20-08-48 | G29: iframegid:conf/iframe/chatItoE_name_js/index.html | H29: 同意する | I29: 理解しました | J29: AIとのチャットの様子を視聴する． | K29: あなた自身がユーザになったつもりでチャットの様子を視聴する | L29: チャット画面をスクロール，またはチャット画面右側に表示されるスクロールバーをドラッグすることでAIとのチャットを見返すことができる． | M29: AIへの印象の評価は，あまり深く考え込まずに自分が感じた印象で評価する． | N29: 6 | O29: 6 | P29: 5 | Q29: 3 | R29: 6 | S29: 5 | T29: 7 | U29: 3 | V29: 5 | W29: 5 | X29: 5 | Y29: 5 | Z29: 6 | AA29: 3 | AB29: 5 | AC29: 5 | AD29: 6 | AE29: 3 | AF29: 5 | AG29: 1 | AH29: 0 | AI29: 0 | AJ29: 0 | AK29: 1 | AL29: 0 | AM29: 1 | AN29: 0 | AO29: 0 | AP29: 0 | AQ29: 0 | AR29: 1 | AS29: 男 | AT29: 50 | AU29: AIを応援した | AV29: あり | AW29: あり | AX29: 人間 | AY29: 1 | BA29: TRUE | BB29: TRUE
A30: 1 | B30: 0 | C30: nszw26001_q8nn3Es0UG | D30: ja | E30: 2026-01-27_20-03-12 | F30: 2026-01-27_20-08-56 | G30: iframegid:conf/iframe/chatItoI_name_js/index.html | H30: 同意する | I30: 理解しました | J30: AIとのチャットの様子を視聴する． | K30: あなた自身がユーザになったつもりでチャットの様子を視聴する | L30: チャット画面をスクロール，またはチャット画面右側に表示されるスクロールバーをドラッグすることでAIとのチャットを見返すことができる． | M30: AIへの印象の評価は，あまり深く考え込まずに自分が感じた印象で評価する． | N30: 7 | O30: 6 | P30: 4 | Q30: 2 | R30: 4 | S30: 3 | T30: 4 | U30: 1 | V30: 4 | W30: 3 | X30: 2 | Y30: 3 | Z30: 6 | AA30: 6 | AB30: 6 | AC30: 4 | AD30: 3 | AE30: 2 | AF30: 6 | AG30: 1 | AH30: 0 | AI30: 0 | AJ30: 0 | AK30: 0 | AL30: 0 | AM30: 1 | AN30: 0 | AO30: 0 | AP30: 0 | AQ30: 0 | AR30: 1 | AS30: 男 | AT30: 54 | AU30: 研究に役立ててください | AV30: なし | AW30: あり | AX30: 人間 | AY30: 1 | BA30: TRUE | BB30: TRUE
A31: 1 | B31: 1 | C31: nszw26001_lKmAxuocXa | D31: ja | E31: 2026-01-27_20-02-33 | F31: 2026-01-27_20-09-03 | G31: iframegid:conf/iframe/chatItoE_name_js/index.html | H31: 同意する | I31: 理解しました | J31: AIとのチャットの様子を視聴する． | K31: あなた自身がユーザになったつもりでチャットの様子を視聴する | L31: チャット画面をスクロール，またはチャット画面右側に表示されるスクロールバーをドラッグすることでAIとのチャットを見返すことができる． | M31: AIへの印象の評価は，あまり深く考え込まずに自分が感じた印象で評価する． | N31: 3 | O31: 3 | P31: 0 | Q31: 0 | R31: 0 | S31: 2 | T31: 3 | U31: 0 | V31: 1 | W31: 5 | X31: 0 | Y31: 0 | Z31: 0 | AA31: 0 | AB31: 0 | AC31: 0 | AD31: 0 | AE31: 0 | AF31: 1 | AG31: 0 | AH31: 0 | AI31: 1 | AJ31: 0 | AK31: 1 | AL31: 0 | AM31: 1 | AN31: 0 | AO31: 0 | AP31: 0 | AQ31: 0 | AR31: 1 | AS31: 男 | AT31: 43 | AU31: アンケート用のテストであることは理解しているが、実際のAIはもう少し賢いような気がした。ただ、クローバーのカードの真ん中の模様のみスペードになっていたりリアルなところもあった。 | AV31: あり | AW31: あり | AX31: 人間 | AY31: 1 | BA31: TRUE | BB31: TRUE
A32: 1 | B32: 1 | C32: nszw26001_IZU9PBKF1A | D32: ja | E32: 2026-01-27_20-03-11 | F32: 2026-01-27_20-09-20 | G32: iframegid:conf/iframe/chatItoE_name_js/index.html | H32: 同意する | I32: 理解しました | J32: AIとのチャットの様子を視聴する． | K32: あなた自身がユーザになったつもりでチャットの様子を視聴する | L32: チャット画面をスクロール，またはチャット画面右側に表示されるスクロールバーをドラッグすることでAIとのチャットを見返すことができる． | M32: AIへの印象の評価は，あまり深く考え込まずに自分が感じた印象で評価する． | N32: 8 | O32: 8 | P32: 5 | Q32: 1 | R32: 5 | S32: 6 | T32: 5 | U32: 0 | V32: 5 | W32: 7 | X32: 4 | Y32: 5 | Z32: 5 | AA32: 5 | AB32: 5 | AC32: 5 | AD32: 5 | AE32: 1 | AF32: 5 | AG32: 1 | AH32: 0 | AI32: 0 | AJ32: 0 | AK32: 1 | AL32: 0 | AM32: 1 | AN32: 0 | AO32: 0 | AP32: 0 | AQ32: 0 | AR32: 1 | AS32: 男 | AT32: 53 | AU32: 簡単だった | AV32: あり | AW32: あり | AX32: 人間 | AY32: 1 | BA32: TRUE | BB32: TRUE
A33: 1 | B33: 0 | C33: nszw26001_vedktIOArY | D33: ja | E33: 2026-01-27_20-04-21 | F33: 2026-01-27_20-09-05 | G33: iframegid:conf/iframe/chatItoI_name_js/index.html | H33: 同意する | I33: 理解しました | J33: AIとのチャットの様子を視聴する． | K33: あなた自身がユーザになったつもりでチャットの様子を視聴する | L33: チャット画面をスクロール，またはチャット画面右側に表示されるスクロールバーをドラッグすることでAIとのチャットを見返すことができる． | M33: AIへの印象の評価は，あまり深く考え込まずに自分が感じた印象で評価する． | N33: 2 | O33: 5 | P33: 1 | Q33: 0 | R33: 3 | S33: 2 | T33: 5 | U33: 1 | V33: 5 | W33: 3 | X33: 1 | Y33: 1 | Z33: 0 | AA33: 0 | AB33: 0 | AC33: 1 | AD33: 1 | AE33: 0 | AF33: 0 | AG33: 1 | AH33: 0 | AI33: 0 | AJ33: 0 | AK33: 0 | AL33: 0 | AM33: 1 | AN33: 0 | AO33: 0 | AP33: 0 | AQ33: 0 | AR33: 1 | AS33: 男 | AT33: 42 | AU33: AIの回答にイライラした | AV33: なし | AW33: あり | AX33: 人間 | AY33: 1 | BA33: TRUE | BB33: TRUE
A34: 0 | B34: 1 | C34: nszw26001_G0wzQyMD7g | D34: ja | E34: 2026-01-27_20-02-30 | F34: 2026-01-27_20-09-07 | G34: iframegid:conf/iframe/chatItoE_noname_js/index.html | H34: 同意する | I34: 理解しました | J34: AIとのチャットの様子を視聴する． | K34: あなた自身がユーザになったつもりでチャットの様子を視聴する | L34: チャット画面をスクロール，またはチャット画面右側に表示されるスクロールバーをドラッグすることでAIとのチャットを見返すことができる． | M34: AIへの印象の評価は，あまり深く考え込まずに自分が感じた印象で評価する． | N34: 6 | O34: 6 | P34: 6 | Q34: 4 | R34: 7 | S34: 5 | T34: 6 | U34: 3 | V34: 5 | W34: 6 | X34: 5 | Y34: 5 | Z34: 6 | AA34: 6 | AB34: 6 | AC34: 7 | AD34: 5 | AE34: 2 | AF34: 4 | AG34: 0 | AH34: 1 | AI34: 0 | AJ34: 0 | AK34: 0 | AL34: 0 | AM34: 0 | AN34: 1 | AO34: 0 | AP34: 0 | AQ34: 0 | AR34: 1 | AS34: 男 | AT34: 49 | AU34: こういう状況よくある | AV34: あり | AW34: なし | AX34: 人間 | AY34: 1 | BA34: TRUE | BB34: TRUE
A35: 1 | B35: 0 | C35: nszw26001_jCVLfrSFeh | D35: ja | E35: 2026-01-27_20-02-31 | F35: 2026-01-27_20-09-09 | G35: iframegid:conf/iframe/chatItoI_name_js/index.html | H35: 同意する | I35: 理解しました | J35: AIとのチャットの様子を視聴する． | K35: あなた自身がユーザになったつもりでチャットの様子を視聴する | L35: チャット画面をスクロール，またはチャット画面右側に表示されるスクロールバーをドラッグすることでAIとのチャットを見返すことができる． | M35: AIへの印象の評価は，あまり深く考え込まずに自分が感じた印象で評価する． | N35: 2 | O35: 2 | P35: 2 | Q35: 1 | R35: 3 | S35: 3 | T35: 3 | U35: 2 | V35: 4 | W35: 5 | X35: 5 | Y35: 6 | Z35: 5 | AA35: 6 | AB35: 5 | AC35: 5 | AD35: 6 | AE35: 2 | AF35: 5 | AG35: 1 | AH35: 0 | AI35: 0 | AJ35: 0 | AK35: 0 | AL35: 0 | AM35: 1 | AN35: 0 | AO35: 0 | AP35: 0 | AQ35: 0 | AR35: 1 | AS35: 男 | AT35: 44 | AU35: プロンプトの工夫が必要だと感じた | AV35: なし | AW35: あり | AX35: 人間 | AY35: 1 | BA35: TRUE | BB35: TRUE
A36: 0 | B36: 0 | C36: nszw26001_zNebVqFwd1 | D36: ja | E36: 2026-01-27_20-02-37 | F36: 2026-01-27_20-09-14 | G36: iframegid:conf/iframe/chatItoI_noname_js/index.html | H36: 同意する | I36: 理解しました | J36: AIとのチャットの様子を視聴する． | K36: あなた自身がユーザになったつもりでチャットの様子を視聴する | L36: チャット画面をスクロール，またはチャット画面右側に表示されるスクロールバーをドラッグすることでAIとのチャットを見返すことができる． | M36: AIへの印象の評価は，あまり深く考え込まずに自分が感じた印象で評価する． | N36: 6 | O36: 7 | P36: 7 | Q36: 4 | R36: 4 | S36: 4 | T36: 7 | U36: 2 | V36: 6 | W36: 6 | X36: 4 | Y36: 5 | Z36: 5 | AA36: 4 | AB36: 4 | AC36: 4 | AD36: 7 | AE36: 2 | AF36: 6 | AG36: 0 | AH36: 0 | AI36: 1 | AJ36: 0 | AK36: 0 | AL36: 0 | AM36: 0 | AN36: 1 | AO36: 0 | AP36: 0 | AQ36: 0 | AR36: 1 | AS36: 男 | AT36: 53 | AU36: 残念なAIでした | AV36: なし | AW36: なし | AX36: 人間 | AY36: 1 | BA36: TRUE | BB36: TRUE
A37: 0 | B37: 1 | C37: nszw26001_gSVHQc8gen | D37: ja | E37: 2026-01-27_20-02-31 | F37: 2026-01-27_20-09-16 | G37: iframegid:conf/iframe/chatItoE_noname_js/index.html | H37: 同意する | I37: 理解しました | J37: AIとのチャットの様子を視聴する． | K37: あなた自身がユーザになったつもりでチャットの様子を視聴する | L37: チャット画面をスクロール，またはチャット画面右側に表示されるスクロールバーをドラッグすることでAIとのチャットを見返すことができる． | M37: AIへの印象の評価は，あまり深く考え込まずに自分が感じた印象で評価する． | N37: 6 | O37: 4 | P37: 7 | Q37: 7 | R37: 7 | S37: 7 | T37: 3 | U37: 5 | V37: 3 | W37: 3 | X37: 5 | Y37: 6 | Z37: 3 | AA37: 3 | AB37: 3 | AC37: 6 | AD37: 4 | AE37: 3 | AF37: 3 | AG37: 1 | AH37: 0 | AI37: 0 | AJ37: 0 | AK37: 0 | AL37: 0 | AM37: 0 | AN37: 1 | AO37: 0 | AP37: 0 | AQ37: 0 | AR37: 1 | AS37: 男 | AT37: 40 | AV37: あり | AW37: なし | AX37: 人間 | AY37: 1 | BA37: TRUE | BB37: TRUE
A38: 0 | B38: 0 | C38: nszw26001_EtIIdDWLQa | D38: ja | E38: 2026-01-27_20-02-37 | F38: 2026-01-27_20-09-36 | G38: iframegid:conf/iframe/chatItoI_noname_js/index.html | H38: 同意する | I38: 理解しました | J38: AIとのチャットの様子を視聴する． | K38: あなた自身がユーザになったつもりでチャットの様子を視聴する | L38: チャット画面をスクロール，またはチャット画面右側に表示されるスクロールバーをドラッグすることでAIとのチャットを見返すことができる． | M38: AIへの印象の評価は，あまり深く考え込まずに自分が感じた印象で評価する． | N38: 0 | O38: 0 | P38: 0 | Q38: 0 | R38: 0 | S38: 0 | T38: 2 | U38: 0 | V38: 0 | W38: 8 | X38: 0 | Y38: 0 | Z38: 2 | AA38: 0 | AB38: 5 | AC38: 0 | AD38: 0 | AE38: 0 | AF38: 2 | AG38: 1 | AH38: 0 | AI38: 0 | AJ38: 0 | AK38: 0 | AL38: 0 | AM38: 0 | AN38: 1 | AO38: 0 | AP38: 0 | AQ38: 0 | AR38: 1 | AS38: 男 | AT38: 59 | AU38: AIのレベルが非常に低いと感じた | AV38: なし | AW38: なし | AX38: 人間 | AY38: 1 | BA38: TRUE | BB38: TRUE
A39: 0 | B39: 0 | C39: nszw26001_oWtJBmkFWo | D39: ja | E39: 2026-01-27_20-02-39 | F39: 2026-01-27_20-09-39 | G39: iframegid:conf/iframe/chatItoI_noname_js/index.html | H39: 同意する | I39: 理解しました | J39: AIとのチャットの様子を視聴する． | K39: あなた自身がユーザになったつもりでチャットの様子を視聴する | L39: チャット画面をスクロール，またはチャット画面右側に表示されるスクロールバーをドラッグすることでAIとのチャットを見返すことができる． | M39: AIへの印象の評価は，あまり深く考え込まずに自分が感じた印象で評価する． | N39: 6 | O39: 2 | P39: 0 | Q39: 0 | R39: 0 | S39: 2 | T39: 6 | U39: 0 | V39: 2 | W39: 2 | X39: 2 | Y39: 2 | Z39: 2 | AA39: 2 | AB39: 10 | AC39: 2 | AD39: 2 | AE39: 0 | AF39: 0 | AG39: 1 | AH39: 0 | AI39: 0 | AJ39: 0 | AK39: 1 | AL39: 1 | AM39: 0 | AN39: 0 | AO39: 0 | AP39: 0 | AQ39: 0 | AR39: 1 | AS39: 男 | AT39: 45 | AV39: なし | AW39: なし | AX39: 人間 | AY39: 1 | BA39: TRUE | BB39: TRUE
A40: 1 | B40: 1 | C40: nszw26001_Fx5qXU4Onc | D40: ja | E40: 2026-01-27_20-04-48 | F40: 2026-01-27_20-09-46 | G40: iframegid:conf/iframe/chatItoE_name_js/index.html | H40: 同意する | I40: 理解しました | J40: AIとのチャットの様子を視聴する． | K40: あなた自身がユーザになったつもりでチャットの様子を視聴する | L40: チャット画面をスクロール，またはチャット画面右側に表示されるスクロールバーをドラッグすることでAIとのチャットを見返すことができる． | M40: AIへの印象の評価は，あまり深く考え込まずに自分が感じた印象で評価する． | N40: 0 | O40: 0 | P40: 0 | Q40: 0 | R40: 0 | S40: 0 | T40: 10 | U40: 0 | V40: 0 | W40: 0 | X40: 0 | Y40: 0 | Z40: 0 | AA40: 0 | AB40: 5 | AC40: 0 | AD40: 0 | AE40: 0 | AF40: 0 | AG40: 0 | AH40: 0 | AI40: 1 | AJ40: 0 | AK40: 1 | AL40: 0 | AM40: 1 | AN40: 0 | AO40: 0 | AP40: 0 | AQ40: 0 | AR40: 1 | AS40: 男 | AT40: 36 | AU40: なし | AV40: あり | AW40: あり | AX40: 人間 | AY40: 1 | BA40: TRUE | BB40: TRUE
...

Sheet Sheet2
A1: 質問 | B1: 人間：PersonaSwitch=あり,HasName=あり | C1: 人間：PersonaSwitch=あり,HasName=なし | D1: 人間：PersonaSwitch=なし,HasName=なし | E1: 人間：PersonaSwitch=なし,HasName=あり
A2: =result!H1 -> Q1 | B2: =AVERAGEIFS(result_h!N$2:'result_h'!N$162,result_h!$AV$2:'result_h'!$AV$162,"あり",result_h!$AW$2:'result_h'!$AW$162,"あり") -> 5.09375 | C2: =AVERAGEIFS(result_h!N$2:'result_h'!N$162,result_h!$AV$2:'result_h'!$AV$162,"あり",result_h!$AW$2:'result_h'!$AW$162,"なし") -> 4.8333333 | D2: =AVERAGEIFS(result_h!N$2:'result_h'!N$162,result_h!$AV$2:'result_h'!$AV$162,"なし",result_h!$AW$2:'result_h'!$AW$162,"なし") -> 4.6578947 | E2: =AVERAGEIFS(result_h!N$2:'result_h'!N$162,result_h!$AV$2:'result_h'!$AV$162,"なし",result_h!$AW$2:'result_h'!$AW$162,"あり") -> 4.3061224
A3: =result!I1 -> Q2 | B3: =AVERAGEIFS(result_h!O$2:'result_h'!O$162,result_h!$AV$2:'result_h'!$AV$162,"あり",result_h!$AW$2:'result_h'!$AW$162,"あり") -> 4.84375 | C3: =AVERAGEIFS(result_h!O$2:'result_h'!O$162,result_h!$AV$2:'result_h'!$AV$162,"あり",result_h!$AW$2:'result_h'!$AW$162,"なし") -> 4.6904762 | D3: =AVERAGEIFS(result_h!O$2:'result_h'!O$162,result_h!$AV$2:'result_h'!$AV$162,"なし",result_h!$AW$2:'result_h'!$AW$162,"なし") -> 4.7894737 | E3: =AVERAGEIFS(result_h!O$2:'result_h'!O$162,result_h!$AV$2:'result_h'!$AV$162,"なし",result_h!$AW$2:'result_h'!$AW$162,"あり") -> 4.1020408
A4: =result!J1 -> Q3 | B4: =AVERAGEIFS(result_h!P$2:'result_h'!P$162,result_h!$AV$2:'result_h'!$AV$162,"あり",result_h!$AW$2:'result_h'!$AW$162,"あり") -> 3.65625 | C4: =AVERAGEIFS(result_h!P$2:'result_h'!P$162,result_h!$AV$2:'result_h'!$AV$162,"あり",result_h!$AW$2:'result_h'!$AW$162,"なし") -> 3.5952381 | D4: =AVERAGEIFS(result_h!P$2:'result_h'!P$162,result_h!$AV$2:'result_h'!$AV$162,"なし",result_h!$AW$2:'result_h'!$AW$162,"なし") -> 4.0526316 | E4: =AVERAGEIFS(result_h!P$2:'result_h'!P$162,result_h!$AV$2:'result_h'!$AV$162,"なし",result_h!$AW$2:'result_h'!$AW$162,"あり") -> 3.1428571
A5: =result!K1 -> Q4 | B5: =AVERAGEIFS(result_h!Q$2:'result_h'!Q$162,result_h!$AV$2:'result_h'!$AV$162,"あり",result_h!$AW$2:'result_h'!$AW$162,"あり") -> 2.21875 | C5: =AVERAGEIFS(result_h!Q$2:'result_h'!Q$162,result_h!$AV$2:'result_h'!$AV$162,"あり",result_h!$AW$2:'result_h'!$AW$162,"なし") -> 2.2142857 | D5: =AVERAGEIFS(result_h!Q$2:'result_h'!Q$162,result_h!$AV$2:'result_h'!$AV$162,"なし",result_h!$AW$2:'result_h'!$AW$162,"なし") -> 2.3684211 | E5: =AVERAGEIFS(result_h!Q$2:'result_h'!Q$162,result_h!$AV$2:'result_h'!$AV$162,"なし",result_h!$AW$2:'result_h'!$AW$162,"あり") -> 1.7755102
A6: =result!L1 -> Q5 | B6: =AVERAGEIFS(result_h!R$2:'result_h'!R$162,result_h!$AV$2:'result_h'!$AV$162,"あり",result_h!$AW$2:'result_h'!$AW$162,"あり") -> 3.53125 | C6: =AVERAGEIFS(result_h!R$2:'result_h'!R$162,result_h!$AV$2:'result_h'!$AV$162,"あり",result_h!$AW$2:'result_h'!$AW$162,"なし") -> 3.4285714 | D6: =AVERAGEIFS(result_h!R$2:'result_h'!R$162,result_h!$AV$2:'result_h'!$AV$162,"なし",result_h!$AW$2:'result_h'!$AW$162,"なし") -> 3.8421053 | E6: =AVERAGEIFS(result_h!R$2:'result_h'!R$162,result_h!$AV$2:'result_h'!$AV$162,"なし",result_h!$AW$2:'result_h'!$AW$162,"あり") -> 3.1020408
A7: =result!M1 -> Q6 | B7: =AVERAGEIFS(result_h!S$2:'result_h'!S$162,result_h!$AV$2:'result_h'!$AV$162,"あり",result_h!$AW$2:'result_h'!$AW$162,"あり") -> 3.6875 | C7: =AVERAGEIFS(result_h!S$2:'result_h'!S$162,result_h!$AV$2:'result_h'!$AV$162,"あり",result_h!$AW$2:'result_h'!$AW$162,"なし") -> 3.7857143 | D7: =AVERAGEIFS(result_h!S$2:'result_h'!S$162,result_h!$AV$2:'result_h'!$AV$162,"なし",result_h!$AW$2:'result_h'!$AW$162,"なし") -> 4.0789474 | E7: =AVERAGEIFS(result_h!S$2:'result_h'!S$162,result_h!$AV$2:'result_h'!$AV$162,"なし",result_h!$AW$2:'result_h'!$AW$162,"あり") -> 3.3265306
A8: =result!N1 -> Q7 | B8: =AVERAGEIFS(result_h!T$2:'result_h'!T$162,result_h!$AV$2:'result_h'!$AV$162,"あり",result_h!$AW$2:'result_h'!$AW$162,"あり") -> 5.59375 | C8: =AVERAGEIFS(result_h!T$2:'result_h'!T$162,result_h!$AV$2:'result_h'!$AV$162,"あり",result_h!$AW$2:'result_h'!$AW$162,"なし") -> 4.8095238 | D8: =AVERAGEIFS(result_h!T$2:'result_h'!T$162,result_h!$AV$2:'result_h'!$AV$162,"なし",result_h!$AW$2:'result_h'!$AW$162,"なし") -> 4.6052632 | E8: =AVERAGEIFS(result_h!T$2:'result_h'!T$162,result_h!$AV$2:'result_h'!$AV$162,"なし",result_h!$AW$2:'result_h'!$AW$162,"あり") -> 3.9387755
A9: =result!O1 -> Q8 | B9: =AVERAGEIFS(result_h!U$2:'result_h'!U$162,result_h!$AV$2:'result_h'!$AV$162,"あり",result_h!$AW$2:'result_h'!$AW$162,"あり") -> 2.25 | C9: =AVERAGEIFS(result_h!U$2:'result_h'!U$162,result_h!$AV$2:'result_h'!$AV$162,"あり",result_h!$AW$2:'result_h'!$AW$162,"なし") -> 2.0238095 | D9: =AVERAGEIFS(result_h!U$2:'result_h'!U$162,result_h!$AV$2:'result_h'!$AV$162,"なし",result_h!$AW$2:'result_h'!$AW$162,"なし") -> 2.6578947 | E9: =AVERAGEIFS(result_h!U$2:'result_h'!U$162,result_h!$AV$2:'result_h'!$AV$162,"なし",result_h!$AW$2:'result_h'!$AW$162,"あり") -> 1.7755102
A10: =result!P1 -> Q10 | B10: =AVERAGEIFS(result_h!V$2:'result_h'!V$162,result_h!$AV$2:'result_h'!$AV$162,"あり",result_h!$AW$2:'result_h'!$AW$162,"あり") -> 3.75 | C10: =AVERAGEIFS(result_h!V$2:'result_h'!V$162,result_h!$AV$2:'result_h'!$AV$162,"あり",result_h!$AW$2:'result_h'!$AW$162,"なし") -> 3.3333333 | D10: =AVERAGEIFS(result_h!V$2:'result_h'!V$162,result_h!$AV$2:'result_h'!$AV$162,"なし",result_h!$AW$2:'result_h'!$AW$162,"なし") -> 4.8157895 | E10: =AVERAGEIFS(result_h!V$2:'result_h'!V$162,result_h!$AV$2:'result_h'!$AV$162,"なし",result_h!$AW$2:'result_h'!$AW$162,"あり") -> 3.4489796
A11: =result!Q1 -> Q11 | B11: =AVERAGEIFS(result_h!W$2:'result_h'!W$162,result_h!$AV$2:'result_h'!$AV$162,"あり",result_h!$AW$2:'result_h'!$AW$162,"あり") -> 4.9375 | C11: =AVERAGEIFS(result_h!W$2:'result_h'!W$162,result_h!$AV$2:'result_h'!$AV$162,"あり",result_h!$AW$2:'result_h'!$AW$162,"なし") -> 4.7619048 | D11: =AVERAGEIFS(result_h!W$2:'result_h'!W$162,result_h!$AV$2:'result_h'!$AV$162,"なし",result_h!$AW$2:'result_h'!$AW$162,"なし") -> 5.7631579 | E11: =AVERAGEIFS(result_h!W$2:'result_h'!W$162,result_h!$AV$2:'result_h'!$AV$162,"なし",result_h!$AW$2:'result_h'!$AW$162,"あり") -> 4.2244898
A12: =result!R1 -> Q12 | B12: =AVERAGEIFS(result_h!X$2:'result_h'!X$162,result_h!$AV$2:'result_h'!$AV$162,"あり",result_h!$AW$2:'result_h'!$AW$162,"あり") -> 2.78125 | C12: =AVERAGEIFS(result_h!X$2:'result_h'!X$162,result_h!$AV$2:'result_h'!$AV$162,"あり",result_h!$AW$2:'result_h'!$AW$162,"なし") -> 2.7142857 | D12: =AVERAGEIFS(result_h!X$2:'result_h'!X$162,result_h!$AV$2:'result_h'!$AV$162,"なし",result_h!$AW$2:'result_h'!$AW$162,"なし") -> 3.6052632 | E12: =AVERAGEIFS(result_h!X$2:'result_h'!X$162,result_h!$AV$2:'result_h'!$AV$162,"なし",result_h!$AW$2:'result_h'!$AW$162,"あり") -> 2.2244898
A13: =result!S1 -> Q13 | B13: =AVERAGEIFS(result_h!Y$2:'result_h'!Y$162,result_h!$AV$2:'result_h'!$AV$162,"あり",result_h!$AW$2:'result_h'!$AW$162,"あり") -> 3.59375 | C13: =AVERAGEIFS(result_h!Y$2:'result_h'!Y$162,result_h!$AV$2:'result_h'!$AV$162,"あり",result_h!$AW$2:'result_h'!$AW$162,"なし") -> 3.3333333 | D13: =AVERAGEIFS(result_h!Y$2:'result_h'!Y$162,result_h!$AV$2:'result_h'!$AV$162,"なし",result_h!$AW$2:'result_h'!$AW$162,"なし") -> 4.2368421 | E13: =AVERAGEIFS(result_h!Y$2:'result_h'!Y$162,result_h!$AV$2:'result_h'!$AV$162,"なし",result_h!$AW$2:'result_h'!$AW$162,"あり") -> 3
A14: =result!T1 -> Q14 | B14: =AVERAGEIFS(result_h!Z$2:'result_h'!Z$162,result_h!$AV$2:'result_h'!$AV$162,"あり",result_h!$AW$2:'result_h'!$AW$162,"あり") -> 3.375 | C14: =AVERAGEIFS(result_h!Z$2:'result_h'!Z$162,result_h!$AV$2:'result_h'!$AV$162,"あり",result_h!$AW$2:'result_h'!$AW$162,"なし") -> 3.5714286 | D14: =AVERAGEIFS(result_h!Z$2:'result_h'!Z$162,result_h!$AV$2:'result_h'!$AV$162,"なし",result_h!$AW$2:'result_h'!$AW$162,"なし") -> 4.4210526 | E14: =AVERAGEIFS(result_h!Z$2:'result_h'!Z$162,result_h!$AV$2:'result_h'!$AV$162,"なし",result_h!$AW$2:'result_h'!$AW$162,"あり") -> 3.4285714
A15: =result!U1 -> Q15 | B15: =AVERAGEIFS(result_h!AA$2:'result_h'!AA$162,result_h!$AV$2:'result_h'!$AV$162,"あり",result_h!$AW$2:'result_h'!$AW$162,"あり") -> 3.4375 | C15: =AVERAGEIFS(result_h!AA$2:'result_h'!AA$162,result_h!$AV$2:'result_h'!$AV$162,"あり",result_h!$AW$2:'result_h'!$AW$162,"なし") -> 3.547619 | D15: =AVERAGEIFS(result_h!AA$2:'result_h'!AA$162,result_h!$AV$2:'result_h'!$AV$162,"なし",result_h!$AW$2:'result_h'!$AW$162,"なし") -> 3.9736842 | E15: =AVERAGEIFS(result_h!AA$2:'result_h'!AA$162,result_h!$AV$2:'result_h'!$AV$162,"なし",result_h!$AW$2:'result_h'!$AW$162,"あり") -> 3.244898
A16: =result!V1 -> Q16 | B16: =AVERAGEIFS(result_h!AB$2:'result_h'!AB$162,result_h!$AV$2:'result_h'!$AV$162,"あり",result_h!$AW$2:'result_h'!$AW$162,"あり") -> 3.625 | C16: =AVERAGEIFS(result_h!AB$2:'result_h'!AB$162,result_h!$AV$2:'result_h'!$AV$162,"あり",result_h!$AW$2:'result_h'!$AW$162,"なし") -> 3.452381 | D16: =AVERAGEIFS(result_h!AB$2:'result_h'!AB$162,result_h!$AV$2:'result_h'!$AV$162,"なし",result_h!$AW$2:'result_h'!$AW$162,"なし") -> 3.8947368 | E16: =AVERAGEIFS(result_h!AB$2:'result_h'!AB$162,result_h!$AV$2:'result_h'!$AV$162,"なし",result_h!$AW$2:'result_h'!$AW$162,"あり") -> 2.6530612
A17: =result!W1 -> Q17 | B17: =AVERAGEIFS(result_h!AC$2:'result_h'!AC$162,result_h!$AV$2:'result_h'!$AV$162,"あり",result_h!$AW$2:'result_h'!$AW$162,"あり") -> 3.53125 | C17: =AVERAGEIFS(result_h!AC$2:'result_h'!AC$162,result_h!$AV$2:'result_h'!$AV$162,"あり",result_h!$AW$2:'result_h'!$AW$162,"なし") -> 3.4285714 | D17: =AVERAGEIFS(result_h!AC$2:'result_h'!AC$162,result_h!$AV$2:'result_h'!$AV$162,"なし",result_h!$AW$2:'result_h'!$AW$162,"なし") -> 4.3421053 | E17: =AVERAGEIFS(result_h!AC$2:'result_h'!AC$162,result_h!$AV$2:'result_h'!$AV$162,"なし",result_h!$AW$2:'result_h'!$AW$162,"あり") -> 3.0816327
A18: =result!X1 -> Q18 | B18: =AVERAGEIFS(result_h!AD$2:'result_h'!AD$162,result_h!$AV$2:'result_h'!$AV$162,"あり",result_h!$AW$2:'result_h'!$AW$162,"あり") -> 4.375 | C18: =AVERAGEIFS(result_h!AD$2:'result_h'!AD$162,result_h!$AV$2:'result_h'!$AV$162,"あり",result_h!$AW$2:'result_h'!$AW$162,"なし") -> 4.2142857 | D18: =AVERAGEIFS(result_h!AD$2:'result_h'!AD$162,result_h!$AV$2:'result_h'!$AV$162,"なし",result_h!$AW$2:'result_h'!$AW$162,"なし") -> 5.0789474 | E18: =AVERAGEIFS(result_h!AD$2:'result_h'!AD$162,result_h!$AV$2:'result_h'!$AV$162,"なし",result_h!$AW$2:'result_h'!$AW$162,"あり") -> 3.8571429
A19: =result!Y1 -> Q19 | B19: =AVERAGEIFS(result_h!AE$2:'result_h'!AE$162,result_h!$AV$2:'result_h'!$AV$162,"あり",result_h!$AW$2:'result_h'!$AW$162,"あり") -> 2.65625 | C19: =AVERAGEIFS(result_h!AE$2:'result_h'!AE$162,result_h!$AV$2:'result_h'!$AV$162,"あり",result_h!$AW$2:'result_h'!$AW$162,"なし") -> 2.1904762 | D19: =AVERAGEIFS(result_h!AE$2:'result_h'!AE$162,result_h!$AV$2:'result_h'!$AV$162,"なし",result_h!$AW$2:'result_h'!$AW$162,"なし") -> 3.0526316 | E19: =AVERAGEIFS(result_h!AE$2:'result_h'!AE$162,result_h!$AV$2:'result_h'!$AV$162,"なし",result_h!$AW$2:'result_h'!$AW$162,"あり") -> 1.8163265
A20: =result!Z1 -> Q20 | B20: =AVERAGEIFS(result_h!AF$2:'result_h'!AF$162,result_h!$AV$2:'result_h'!$AV$162,"あり",result_h!$AW$2:'result_h'!$AW$162,"あり") -> 3.0625 | C20: =AVERAGEIFS(result_h!AF$2:'result_h'!AF$162,result_h!$AV$2:'result_h'!$AV$162,"あり",result_h!$AW$2:'result_h'!$AW$162,"なし") -> 2.7619048 | D20: =AVERAGEIFS(result_h!AF$2:'result_h'!AF$162,result_h!$AV$2:'result_h'!$AV$162,"なし",result_h!$AW$2:'result_h'!$AW$162,"なし") -> 3.4736842 | E20: =AVERAGEIFS(result_h!AF$2:'result_h'!AF$162,result_h!$AV$2:'result_h'!$AV$162,"なし",result_h!$AW$2:'result_h'!$AW$162,"あり") -> 2.0408163
A22: LLM
A23: 質問 | B23: LLM:PersonaSwitch=あり,HasName=あり | C23: LLM:PersonaSwitch=あり,HasName=なし | D23: LLM:PersonaSwitch=なし,HasName=なし | E23: LLM:PersonaSwitch=なし,HasName=あり
A24: Q1 | B24: 3.2857143 | C24: 3.4 | D24: 2.9714286 | E24: 3.2982456
A25: Q2 | B25: 2.2571429 | C25: 2.4 | D25: 1.9714286 | E25: 2.1754386
A26: Q3 | B26: 1.0857143 | C26: 1.0285714 | D26: 0.91428571 | E26: 0.92982456
A27: Q4 | B27: 0.14285714 | C27: 0.25714286 | D27: 0.057142857 | E27: 0.087719298
A28: Q5 | B28: 2.6571429 | C28: 2.5428571 | D28: 2.3714286 | E28: 2.3684211
A29: Q6 | B29: 1.5142857 | C29: 1.6285714 | D29: 1.4 | E29: 1.5789474
A30: Q7 | B30: 4.8 | C30: 2.9142857 | D30: 2.4285714 | E30: 2.9824561
A31: Q8 | B31: 0.74285714 | C31: 0.71428571 | D31: 0.57142857 | E31: 0.49122807
A32: Q10 | B32: 1.4285714 | C32: 1.2285714 | D32: 1.0857143 | E32: 1.0701754
A33: Q11 | B33: 3.3714286 | C33: 3.4285714 | D33: 3.3428571 | E33: 3.3684211
A34: Q12 | B34: 0.17142857 | C34: 0.25714286 | D34: 0.085714286 | E34: 0.087719298
A35: Q13 | B35: 0.94285714 | C35: 0.82857143 | D35: 0.82857143 | E35: 0.71929825
... A42: Q20 | B42: 1.7428571 | C42: 1.4 | D42: 1.2857143 | E42: 1.6140351
